#VRML_SIM R2021a utf8
WorldInfo {
  info [
    "Arena for Stage 1 of SLRC2021 University Category"
  ]
  title "SLRC2021 UniS1"
  coordinateSystem "NUE"
}
Viewpoint {
  orientation 0.9705406780213844 -0.17983096452294114 0.16034842220782833 5.9064432590089915
  position 0.367157199232897 0.618008382064847 1.5451194606879126
}
DirectionalLight {
  direction 0 -1 0
}
DirectionalLight {
  direction -1 -1 0
}
DirectionalLight {
  direction 0 -1 -1
}
DirectionalLight {
  direction 1 -1 0
}
DirectionalLight {
  direction 0 -1 1
}
DEF _ RectangleArena {
  translation -0.02 0 0
  name "Floor_black"
  floorSize 3 4
  floorTileSize 2 2
  floorAppearance Parquetry {
    type "dark strip"
    colorOverride 0 0 0
  }
  wallAppearance DEF Wall_white PBRAppearance {
    roughness 1
    metalness 0
    name "Wall_white"
  }
}
DEF Line Solid {
  translation -0.613 -0.00485 -1.5
  scale 0.01 0.01 0.01
  children [
    Shape {
      appearance PBRAppearance {
        roughness 1
        metalness 0
      }
      geometry Mesh {
        url [
          "../solidworks/Lines.STL"
        ]
      }
      castShadows FALSE
      isPickable FALSE
    }
  ]
  name "White_lines"
  locked TRUE
  translationStep 0
  rotationStep 0
}
DEF Squares Group {
  children [
    DEF Patch Solid {
      translation -0.075 -0.00484 1.1
      scale 0.01 0.01 0.01
      children [
        Shape {
          appearance PBRAppearance {
            baseColor 1 0 0
            roughness 1
            metalness 0
          }
          geometry Mesh {
            url [
              "../solidworks/Square.STL"
            ]
          }
          castShadows FALSE
          isPickable FALSE
        }
      ]
      name "color_patch"
      locked TRUE
      translationStep 0
      rotationStep 0
    }
    DEF Green Solid {
      translation 0.01 -0.00484 -1.65
      scale 0.01 0.01 0.01
      children [
        Shape {
          appearance PBRAppearance {
            baseColor 0 1 0
            roughness 1
            metalness 0
          }
          geometry Mesh {
            url [
              "../solidworks/Square.STL"
            ]
          }
          castShadows FALSE
          isPickable FALSE
        }
      ]
      name "green_square"
      locked TRUE
      translationStep 0
      rotationStep 0
    }
    DEF Red Solid {
      translation -0.41 -0.00484 -1.65
      scale 0.01 0.01 0.01
      children [
        Shape {
          appearance PBRAppearance {
            baseColor 1 0 0
            roughness 1
            metalness 0
          }
          geometry Mesh {
            url [
              "../solidworks/Square.STL"
            ]
          }
          castShadows FALSE
          isPickable FALSE
        }
      ]
      name "red_square"
      locked TRUE
      translationStep 0
      rotationStep 0
    }
    DEF Blue Solid {
      translation 0.43 -0.00484 -1.65
      scale 0.01 0.01 0.01
      children [
        Shape {
          appearance PBRAppearance {
            baseColor 0 0 1
            roughness 1
            metalness 0
          }
          geometry Mesh {
            url [
              "../solidworks/Square.STL"
            ]
          }
          castShadows FALSE
          isPickable FALSE
        }
      ]
      name "blue_square"
      locked TRUE
      translationStep 0
      rotationStep 0
    }
  ]
}
DEF Inner_wall Solid {
  translation 0.005 0 -0.66
  scale 0.01 0.01 0.01
  children [
    DEF Inner_wall Shape {
      appearance USE Wall_white
      geometry Mesh {
        url [
          "../solidworks/Inner_walls.STL"
        ]
      }
    }
  ]
  name "Inner_walls"
  boundingObject USE Inner_wall
  locked TRUE
  recognitionColors [
    1 1 1
  ]
  translationStep 0
  rotationStep 0
}
DEF Inner_wall Solid {
  translation 0.33 0 -1.4
  scale 0.01 0.01 0.01
  children [
    DEF Inner_wall Shape {
      appearance USE Wall_white
      geometry Mesh {
        url [
          "../solidworks/Inner_walls.STL"
        ]
      }
    }
  ]
  name "Inner_walls(1)"
  boundingObject USE Inner_wall
  locked TRUE
  recognitionColors [
    1 1 1
  ]
  translationStep 0
  rotationStep 0
}
DEF Right_pillar Solid {
  translation 0.2 0.02 0.74
  children [
    Shape {
      appearance PBRAppearance {
        roughness 1
        metalness 0
      }
      geometry Box {
        size 0.02 0.04 0.12
      }
    }
  ]
  name "R_pillar"
  radarCrossSection 1
}
DEF Left_pillar Solid {
  translation -0.12 0.04 0.74
  children [
    Shape {
      appearance PBRAppearance {
        roughness 1
        metalness 0
      }
      geometry Box {
        size 0.02 0.09 0.12
      }
    }
  ]
  name "L_pillar"
  radarCrossSection 1
}
Robot {
  translation 0.305509 0.00408541 0.383457
  rotation -3.298919310346019e-05 -0.9999977909459455 0.0021016695606364865 3.14116
  children [
    DEF body Transform {
      translation 0 0.02 0
      rotation 0 1 0 1.5708
      children [
        Shape {
          appearance PBRAppearance {
            baseColor 0.815686 1 0.388235
            roughness 1
            metalness 0
          }
          geometry Box {
            size 0.12 0.01 0.1
          }
        }
      ]
    }
    DEF right_wheel HingeJoint {
      jointParameters HingeJointParameters {
        position 1815.1042372323125
        anchor -0.055 0.02 -0.03
      }
      device [
        RotationalMotor {
          name "left_motor"
        }
      ]
      endPoint Solid {
        translation -0.05499999411369054 0.020006551415642563 -0.0299957593644506
        rotation 0.27890566235368786 0.27890647026233245 -0.9189248132207865 1.6552450337883498
        children [
          DEF wheel Shape {
            appearance PBRAppearance {
              baseColor 0 0.333333 0
              roughness 1
              metalness 0
            }
            geometry Cylinder {
              height 0.01
              radius 0.02
            }
          }
        ]
        boundingObject USE wheel
        physics Physics {
        }
      }
    }
    DEF left_wheel HingeJoint {
      jointParameters HingeJointParameters {
        position 1797.4831890212959
        anchor 0.055 0.02 -0.03
      }
      device [
        RotationalMotor {
          name "right_motor"
        }
      ]
      endPoint Solid {
        translation 0.055000005865753036 0.019998242227893554 -0.029992612027832363
        rotation -0.6193414437439912 -0.6193412423003136 0.48252730663353405 4.040738980034544
        children [
          Shape {
            appearance PBRAppearance {
              baseColor 0 0.333333 0
              roughness 1
              metalness 0
            }
            geometry Cylinder {
              height 0.01
              radius 0.02
            }
          }
        ]
        name "solid(1)"
        boundingObject USE wheel
        physics Physics {
        }
      }
    }
    DEF piller_detect HingeJoint {
      jointParameters HingeJointParameters {
        position 6.23999999492101
        axis 0 1 0
        anchor 0 0.045 0
      }
      device [
        RotationalMotor {
          name "piller_detect_bottom"
        }
      ]
      endPoint Solid {
        translation 0 0.045 0
        rotation 0 1 0 3.14
        children [
          DEF sensor Shape {
            appearance PBRAppearance {
              baseColor 1 0.666667 1
              roughness 1
              metalness 0
            }
            geometry Cylinder {
              height 0.04
              radius 0.01
            }
          }
          DistanceSensor {
            translation 0 -0.015 0
            rotation 0 1 0 1.5708
            name "bottom_sensor"
            lookupTable [
              0 0 0
              0.4 1000 0
            ]
            type "infra-red"
          }
          DistanceSensor {
            rotation 0 1 0 1.5708
            name "top_sensor"
            lookupTable [
              0 0 0
              0.4 1000 0
            ]
            type "infra-red"
          }
        ]
        name "solid(3)"
        boundingObject USE sensor
        physics Physics {
        }
      }
    }
    DEF support_ball Solid {
      translation 0 0.0075 0.05
      rotation 0 0 -1 2.3276357876976306e-07
      children [
        DEF ball Shape {
          appearance PBRAppearance {
            roughness 1
            metalness 0
          }
          geometry Sphere {
            radius 0.0075
          }
        }
      ]
      name "solid(2)"
      boundingObject USE ball
      physics Physics {
      }
    }
    DEF left_2 DistanceSensor {
      translation 0.046 0.02 0.06
      rotation 0 0 1 0
      children [
        Shape {
          appearance PBRAppearance {
            baseColor 0.666667 0 0.498039
            roughness 1
            metalness 0
          }
          geometry Box {
            size 0.008 0.008 0.008
          }
        }
      ]
      name "left2_ir"
      lookupTable [
        0 0 0
        0.2 1000 0
      ]
      type "infra-red"
    }
    DEF left DistanceSensor {
      translation 0.017 0.02 0.06
      rotation 0 0 1 -1.5707
      children [
        Shape {
          appearance PBRAppearance {
            baseColor 0.0235294 0.0352941 0.85098
            roughness 1
            metalness 0
          }
          geometry Box {
            size 0.008 0.008 0.008
          }
        }
      ]
      name "left_ir"
      type "infra-red"
    }
    DEF center DistanceSensor {
      translation 0 0.02 0.06
      rotation 0 0 1 -1.5707
      children [
        Shape {
          appearance PBRAppearance {
            baseColor 0.0235294 0.0352941 0.85098
            roughness 1
            metalness 0
          }
          geometry Box {
            size 0.008 0.008 0.008
          }
        }
      ]
      name "center_ir"
      type "infra-red"
    }
    DEF right DistanceSensor {
      translation -0.017 0.02 0.06
      rotation 0 0 1 -1.5707
      children [
        Shape {
          appearance PBRAppearance {
            baseColor 0.0235294 0.0352941 0.85098
            roughness 1
            metalness 0
          }
          geometry Box {
            size 0.008 0.008 0.008
          }
        }
      ]
      name "right_ir"
      type "infra-red"
    }
    DEF right_2 DistanceSensor {
      translation -0.046 0.02 0.06
      rotation 0 0 1 3.14
      children [
        Shape {
          appearance PBRAppearance {
            baseColor 0.666667 0 0.498039
            roughness 1
            metalness 0
          }
          geometry Box {
            size 0.008 0.008 0.008
          }
        }
      ]
      name "right2_ir"
      lookupTable [
        0 0 0
        0.2 1000 0
      ]
      type "infra-red"
    }
    Camera {
      translation 0 0.02 0.06
      rotation 1 0 0 -1.5707996938995747
      children [
        Solid {
          children [
            Shape {
              appearance PBRAppearance {
                baseColor 1 0 0
                roughness 1
                metalness 0
              }
              geometry Box {
                size 0.01 0.01 0.01
              }
            }
          ]
        }
      ]
      recognitionColors [
        0 0 0
      ]
    }
  ]
  boundingObject USE body
  physics Physics {
    mass 1
  }
  controller "wall_follow"
  controllerArgs [
    ""
  ]
}
